Workbook

Sheet Data
A1: 5.1 | B1: 3.5 | C1: 1.4 | D1: 0.2 | E1: Iris-setosa
A2: 4.9 | B2: 3 | C2: 1.4 | D2: 0.2 | E2: Iris-setosa
A3: 4.7 | B3: 3.2 | C3: 1.3 | D3: 0.2 | E3: Iris-setosa
A4: 4.6 | B4: 3.1 | C4: 1.5 | D4: 0.2 | E4: Iris-setosa
A5: 5 | B5: 3.6 | C5: 1.4 | D5: 0.2 | E5: Iris-setosa
A6: 5.4 | B6: 3.9 | C6: 1.7 | D6: 0.4 | E6: Iris-setosa
A7: 4.6 | B7: 3.4 | C7: 1.4 | D7: 0.3 | E7: Iris-setosa
A8: 5 | B8: 3.4 | C8: 1.5 | D8: 0.2 | E8: Iris-setosa
A9: 4.4 | B9: 2.9 | C9: 1.4 | D9: 0.2 | E9: Iris-setosa
A10: 4.9 | B10: 3.1 | C10: 1.5 | D10: 0.1 | E10: Iris-setosa
A11: 5.4 | B11: 3.7 | C11: 1.5 | D11: 0.2 | E11: Iris-setosa
A12: 4.8 | B12: 3.4 | C12: 1.6 | D12: 0.2 | E12: Iris-setosa
... A100: 5.7 | B100: 2.8 | C100: 4.1 | D100: 1.3 | E100: Iris-versicolor

Sheet SLP-Training
G2: Setosa = 0 | I2: Learning Rate | K2: 0.1
G3: Versicolor = 1 | H3: Accuracy | I3: Bobot bias | N3: dot product | O3: Sigmoid | P3: Prediksi | Q3: error | R3: Sum Square Error | S3: MSE (avg) | Z3: Epoch | AA3: MSE (Train) | AB3: Accuracy (Train)
A4: EPOCH | B4: No | C4: X1 | D4: X2 | E4: X3 | F4: X4 | G4: TARGET | I4: bias | J4: teta1 | K4: teta2 | L4: teta 3 | M4: teta4 | N4: z | O4: g(z) | T4: dbias | U4: dteta1 | V4: dteta2 | W4: dteta3 | X4: dteta4 | Z4: 1 | AA4: =S84 -> 0.1299649 | AB4: =H84 -> 0.85
A5: epoch1 | B5: 1 | C5: 5.1 | D5: 3.5 | E5: 1.4 | F5: 0.2 | G5: 0 | I5: 0.5 | J5: 0.5 | K5: 0.5 | L5: 0.5 | M5: 0.5 | N5: =I5+J5*C5+K5*D5+L5*E5+F5*M5 -> 5.6 | O5: =1/(1+EXP(-N5)) -> 0.99631576 | P5: =IF(O5>0.5,1,0) -> 1 | Q5: =O5-G5 -> 0.99631576 | R5: =Q5^2 -> 0.99264509 | T5: =2*(O5-G5)*(1-O5)*O5 -> 0.0073142853 | U5: =2*(O5-G5)*(1-O5)*O5*C5 -> 0.037302855 | V5: =2*(O5-G5)*(1-O5)*O5*D5 -> 0.025599999 | W5: =2*(O5-G5)*(1-O5)*O5*E5 -> 0.010239999 | X5: =2*(O5-G5)*(1-O5)*O5*F5 -> 0.0014628571 | Z5: 2 | AA5: =S164 -> 0.034548306 | AB5: =H164 -> 0.95
B6: 2 | C6: 4.9 | D6: 3 | E6: 1.4 | F6: 0.2 | G6: 0 | I6: =I5-K2*T5 -> 0.49926857 | J6: =J5-K2*U5 -> 0.49626971 | K6: =K5-K2*V5 -> 0.49744 | L6: =L5-K2*W5 -> 0.498976 | M6: =M5-K2*X5 -> 0.49985371 | N6: =I6+J6*C6+K6*D6+L6*E6+F6*M6 -> 5.2218473 | O6: =1/(1+EXP(-N6)) -> 0.99463163 | P6: =IF(O6>0.5,1,0) -> 1 | Q6: =O6-G6 -> 0.99463163 | R6: =Q6^2 -> 0.98929207 | T6: =2*(O6-G6)*(1-O6)*O6 -> 0.01062178 | U6: =2*(O6-G6)*(1-O6)*O6*C6 -> 0.052046723 | V6: =2*(O6-G6)*(1-O6)*O6*D6 -> 0.031865341 | W6: =2*(O6-G6)*(1-O6)*O6*E6 -> 0.014870492 | X6: =2*(O6-G6)*(1-O6)*O6*F6 -> 0.0021243561 | Z6: 3 | AA6: =S244 -> 0.022989957 | AB6: =H244 -> 0.975
B7: 3 | C7: 4.7 | D7: 3.2 | E7: 1.3 | F7: 0.2 | G7: 0 | I7: =I6-K2*T6 -> 0.49820639 | J7: =J6-K2*U6 -> 0.49106504 | K7: =K6-K2*V6 -> 0.49425347 | L7: =L6-K2*W6 -> 0.49748895 | M7: =M6-K2*X6 -> 0.49964128 | N7: =I7+J7*C7+K7*D7+L7*E7+F7*M7 -> 5.1344871 | O7: =1/(1+EXP(-N7)) -> 0.99414442 | P7: =IF(O7>0.5,1,0) -> 1 | Q7: =O7-G7 -> 0.99414442 | R7: =Q7^2 -> 0.98832312 | T7: =2*(O7-G7)*(1-O7)*O7 -> 0.011574414 | U7: =2*(O7-G7)*(1-O7)*O7*C7 -> 0.054399748 | V7: =2*(O7-G7)*(1-O7)*O7*D7 -> 0.037038126 | W7: =2*(O7-G7)*(1-O7)*O7*E7 -> 0.015046739 | X7: =2*(O7-G7)*(1-O7)*O7*F7 -> 0.0023148829 | Z7: 4 | AA7: =S324 -> 0.016535227 | AB7: =H324 -> 0.975
B8: 4 | C8: 4.6 | D8: 3.1 | E8: 1.5 | F8: 0.2 | G8: 0 | I8: =I7-K2*T7 -> 0.49704895 | J8: =J7-K2*U7 -> 0.48562507 | K8: =K7-K2*V7 -> 0.49054965 | L8: =L7-K2*W7 -> 0.49598428 | M8: =M7-K2*X7 -> 0.49940979 | N8: =I8+J8*C8+K8*D8+L8*E8+F8*M8 -> 5.0954866 | O8: =1/(1+EXP(-N8)) -> 0.99391295 | P8: =IF(O8>0.5,1,0) -> 1 | Q8: =O8-G8 -> 0.99391295 | R8: =Q8^2 -> 0.98786296 | T8: =2*(O8-G8)*(1-O8)*O8 -> 0.012026336 | U8: 5 | V8: =2*(O8-G8)*(1-O8)*O8*D8 -> 0.037281643 | W8: =2*(O8-G8)*(1-O8)*O8*E8 -> 0.018039505 | X8: =2*(O8-G8)*(1-O8)*O8*F8 -> 0.0024052673 | Z8: 5 | AA8: =S404 -> 0.012222388 | AB8: =H404 -> 0.9875
B9: 5 | C9: 5 | D9: 3.6 | E9: 1.4 | F9: 0.2 | G9: 0 | I9: =I8-K2*T8 -> 0.49584632 | J9: =J8-K2*U8 -> -0.014374933 | K9: =K8-K2*V8 -> 0.48682149 | L9: =L8-K2*W8 -> 0.49418033 | M9: =M8-K2*X8 -> 0.49916926 | N9: =I9+J9*C9+K9*D9+L9*E9+F9*M9 -> 2.9682153 | O9: =1/(1+EXP(-N9)) -> 0.95111737 | P9: =IF(O9>0.5,1,0) -> 1 | Q9: =O9-G9 -> 0.95111737 | R9: =Q9^2 -> 0.90462425 | T9: =2*(O9-G9)*(1-O9)*O9 -> 0.088440827 | U9: =2*(O9-G9)*(1-O9)*O9*C9 -> 0.44220414 | V9: =2*(O9-G9)*(1-O9)*O9*D9 -> 0.31838698 | W9: =2*(O9-G9)*(1-O9)*O9*E9 -> 0.12381716 | X9: =2*(O9-G9)*(1-O9)*O9*F9 -> 0.017688165
B10: 6 | C10: 5.4 | D10: 3.9 | E10: 1.7 | F10: 0.4 | G10: 0 | I10: =I9-K2*T9 -> 0.48700224 | J10: =J9-K2*U9 -> -0.058595346 | K10: =K9-K2*V9 -> 0.45498279 | L10: =L9-K2*W9 -> 0.48179861 | M10: =M9-K2*X9 -> 0.49740045 | N10: =I10+J10*C10+K10*D10+L10*E10+F10*M10 -> 2.9630381 | O10: =1/(1+EXP(-N10)) -> 0.9508761 | P10: =IF(O10>0.5,1,0) -> 1 | Q10: =O10-G10 -> 0.9508761 | R10: =Q10^2 -> 0.90416536 | T10: =2*(O10-G10)*(1-O10)*O10 -> 0.088832259 | U10: =2*(O10-G10)*(1-O10)*O10*C10 -> 0.4796942 | V10: =2*(O10-G10)*(1-O10)*O10*D10 -> 0.34644581 | W10: =2*(O10-G10)*(1-O10)*O10*E10 -> 0.15101484 | X10: =2*(O10-G10)*(1-O10)*O10*F10 -> 0.035532904
B11: 7 | C11: 4.6 | D11: 3.4 | E11: 1.4 | F11: 0.3 | G11: 0 | I11: =I10-K2*T10 -> 0.47811901 | J11: =J10-K2*U10 -> -0.10656477 | K11: =K10-K2*V10 -> 0.42033821 | L11: =L10-K2*W10 -> 0.46669713 | M11: =M10-K2*X10 -> 0.49384716 | N11: =I11+J11*C11+K11*D11+L11*E11+F11*M11 -> 2.2186011 | O11: =1/(1+EXP(-N11)) -> 0.90190751 | P11: =IF(O11>0.5,1,0) -> 1 | Q11: =O11-G11 -> 0.90190751 | R11: =Q11^2 -> 0.81343715 | T11: =2*(O11-G11)*(1-O11)*O11 -> 0.15958416 | U11: =2*(O11-G11)*(1-O11)*O11*C11 -> 0.73408712 | V11: =2*(O11-G11)*(1-O11)*O11*D11 -> 0.54258613 | W11: =2*(O11-G11)*(1-O11)*O11*E11 -> 0.22341782 | X11: =2*(O11-G11)*(1-O11)*O11*F11 -> 0.047875247
B12: 8 | C12: 5 | D12: 3.4 | E12: 1.5 | F12: 0.2 | G12: 0 | I12: =I11-K2*T11 -> 0.46216059 | J12: =J11-K2*U11 -> -0.17997348 | K12: =K11-K2*V11 -> 0.3660796 | L12: =L11-K2*W11 -> 0.44435534 | M12: =M11-K2*X11 -> 0.48905963 | N12: =I12+J12*C12+K12*D12+L12*E12+F12*M12 -> 1.5713088 | O12: =1/(1+EXP(-N12)) -> 0.8279701 | P12: =IF(O12>0.5,1,0) -> 1 | Q12: =O12-G12 -> 0.8279701 | R12: =Q12^2 -> 0.68553449 | T12: =2*(O12-G12)*(1-O12)*O12 -> 0.23586485 | U12: =2*(O12-G12)*(1-O12)*O12*C12 -> 1.1793243 | V12: =2*(O12-G12)*(1-O12)*O12*D12 -> 0.80194051 | W12: =2*(O12-G12)*(1-O12)*O12*E12 -> 0.35379728 | X12: =2*(O12-G12)*(1-O12)*O12*F12 -> 0.047172971
B13: 9 | C13: 4.4 | D13: 2.9 | E13: 1.4 | F13: 0.2 | G13: 0 | I13: =I12-K2*T12 -> 0.43857411 | J13: =J12-K2*U12 -> -0.29790591 | K13: =K12-K2*V12 -> 0.28588555 | L13: =L12-K2*W12 -> 0.40897562 | M13: =M12-K2*X12 -> 0.48434233 | N13: =I13+J13*C13+K13*D13+L13*E13+F13*M13 -> 0.62629054 | O13: =1/(1+EXP(-N13)) -> 0.65164788 | P13: =IF(O13>0.5,1,0) -> 1 | Q13: =O13-G13 -> 0.65164788 | R13: =Q13^2 -> 0.42464496 | T13: =2*(O13-G13)*(1-O13)*O13 -> 0.29585194 | U13: =2*(O13-G13)*(1-O13)*O13*C13 -> 1.3017486 | V13: =2*(O13-G13)*(1-O13)*O13*D13 -> 0.85797064 | W13: =2*(O13-G13)*(1-O13)*O13*E13 -> 0.41419272 | X13: =2*(O13-G13)*(1-O13)*O13*F13 -> 0.059170389
B14: 10 | C14: 4.9 | D14: 3.1 | E14: 1.5 | F14: 0.1 | G14: 0 | I14: =I13-K2*T13 -> 0.40898891 | J14: =J13-K2*U13 -> -0.42808076 | K14: =K13-K2*V13 -> 0.20008848 | L14: =L13-K2*W13 -> 0.36755634 | M14: =M13-K2*X13 -> 0.4784253 | N14: =I14+J14*C14+K14*D14+L14*E14+F14*M14 -> -0.46915547 | O14: =1/(1+EXP(-N14)) -> 0.38481615 | P14: =IF(O14>0.5,1,0) -> 0 | Q14: =O14-G14 -> 0.38481615 | R14: =Q14^2 -> 0.14808347 | T14: =2*(O14-G14)*(1-O14)*O14 -> 0.18219712 | U14: =2*(O14-G14)*(1-O14)*O14*C14 -> 0.89276588 | V14: =2*(O14-G14)*(1-O14)*O14*D14 -> 0.56481107 | W14: =2*(O14-G14)*(1-O14)*O14*E14 -> 0.27329568 | X14: =2*(O14-G14)*(1-O14)*O14*F14 -> 0.018219712
B15: 11 | C15: 5.4 | D15: 3.7 | E15: 1.5 | F15: 0.2 | G15: 0 | I15: =I14-K2*T14 -> 0.3907692 | J15: =J14-K2*U14 -> -0.51735735 | K15: =K14-K2*V14 -> 0.14360738 | L15: =L14-K2*W14 -> 0.34022678 | M15: =M14-K2*X14 -> 0.47660332 | N15: =I15+J15*C15+K15*D15+L15*E15+F15*M15 -> -1.2659524 | O15: =1/(1+EXP(-N15)) -> 0.21995093 | P15: =IF(O15>0.5,1,0) -> 0 | Q15: =O15-G15 -> 0.21995093 | R15: =Q15^2 -> 0.048378411 | T15: =2*(O15-G15)*(1-O15)*O15 -> 0.075475069 | U15: =2*(O15-G15)*(1-O15)*O15*C15 -> 0.40756537 | V15: =2*(O15-G15)*(1-O15)*O15*D15 -> 0.27925776 | W15: =2*(O15-G15)*(1-O15)*O15*E15 -> 0.1132126 | X15: =2*(O15-G15)*(1-O15)*O15*F15 -> 0.015095014
B16: 12 | C16: 4.8 | D16: 3.4 | E16: 1.6 | F16: 0.2 | G16: 0 | I16: =I15-K2*T15 -> 0.3832217 | J16: =J15-K2*U15 -> -0.55811389 | K16: =K15-K2*V15 -> 0.1156816 | L16: =L15-K2*W15 -> 0.32890552 | M16: =M15-K2*X15 -> 0.47509382 | N16: =I16+J16*C16+K16*D16+L16*E16+F16*M16 -> -1.2811399 | O16: =1/(1+EXP(-N16)) -> 0.21735625 | P16: =IF(O16>0.5,1,0) -> 0 | Q16: =O16-G16 -> 0.21735625 | R16: =Q16^2 -> 0.047243737 | T16: =2*(O16-G16)*(1-O16)*O16 -> 0.073950032 | U16: =2*(O16-G16)*(1-O16)*O16*C16 -> 0.35496015 | V16: =2*(O16-G16)*(1-O16)*O16*D16 -> 0.25143011 | W16: =2*(O16-G16)*(1-O16)*O16*E16 -> 0.11832005 | X16: =2*(O16-G16)*(1-O16)*O16*F16 -> 0.014790006
B17: 13 | C17: 4.8 | D17: 3 | E17: 1.4 | F17: 0.1 | G17: 0 | I17: =I16-K2*T16 -> 0.37582669 | J17: =J16-K2*U16 -> -0.5936099 | K17: =K16-K2*V16 -> 0.09053859 | L17: =L16-K2*W16 -> 0.31707351 | M17: =M16-K2*X16 -> 0.47361482 | N17: =I17+J17*C17+K17*D17+L17*E17+F17*M17 -> -1.7106207 | O17: =1/(1+EXP(-N17)) -> 0.15308323 | P17: =IF(O17>0.5,1,0) -> 0 | Q17: =O17-G17 -> 0.15308323 | R17: =Q17^2 -> 0.023434475 | T17: =2*(O17-G17)*(1-O17)*O17 -> 0.0396941 | U17: =2*(O17-G17)*(1-O17)*O17*C17 -> 0.19053168 | V17: =2*(O17-G17)*(1-O17)*O17*D17 -> 0.1190823 | W17: =2*(O17-G17)*(1-O17)*O17*E17 -> 0.05557174 | X17: =2*(O17-G17)*(1-O17)*O17*F17 -> 0.00396941
B18: 14 | C18: 4.3 | D18: 3 | E18: 1.1 | F18: 0.1 | G18: 0 | I18: =I17-K2*T17 -> 0.37185728 | J18: =J17-K2*U17 -> -0.61266307 | K18: =K17-K2*V17 -> 0.07863036 | L18: =L17-K2*W17 -> 0.31151634 | M18: =M17-K2*X17 -> 0.47321788 | N18: =I18+J18*C18+K18*D18+L18*E18+F18*M18 -> -1.6367131 | O18: =1/(1+EXP(-N18)) -> 0.16291281 | P18: =IF(O18>0.5,1,0) -> 0 | Q18: =O18-G18 -> 0.16291281 | R18: =Q18^2 -> 0.026540584 | T18: =2*(O18-G18)*(1-O18)*O18 -> 0.044433566 | U18: =2*(O18-G18)*(1-O18)*O18*C18 -> 0.19106433 | V18: =2*(O18-G18)*(1-O18)*O18*D18 -> 0.1333007 | W18: =2*(O18-G18)*(1-O18)*O18*E18 -> 0.048876922 | X18: =2*(O18-G18)*(1-O18)*O18*F18 -> 0.0044433566
B19: 15 | C19: 5.8 | D19: 4 | E19: 1.2 | F19: 0.2 | G19: 0 | I19: =I18-K2*T18 -> 0.36741393 | J19: =J18-K2*U18 -> -0.6317695 | K19: =K18-K2*V18 -> 0.06530029 | L19: =L18-K2*W18 -> 0.30662864 | M19: =M18-K2*X18 -> 0.47277355 | N19: =I19+J19*C19+K19*D19+L19*E19+F19*M19 -> -2.5731389 | O19: =1/(1+EXP(-N19)) -> 0.070887287 | P19: =IF(O19>0.5,1,0) -> 0 | Q19: =O19-G19 -> 0.070887287 | R19: =Q19^2 -> 0.0050250075 | T19: =2*(O19-G19)*(1-O19)*O19 -> 0.0093375967 | U19: =2*(O19-G19)*(1-O19)*O19*C19 -> 0.054158061 | V19: =2*(O19-G19)*(1-O19)*O19*D19 -> 0.037350387 | W19: =2*(O19-G19)*(1-O19)*O19*E19 -> 0.011205116 | X19: =2*(O19-G19)*(1-O19)*O19*F19 -> 0.0018675193
B20: 16 | C20: 5.7 | D20: 4.4 | E20: 1.5 | F20: 0.4 | G20: 0 | I20: =I19-K2*T19 -> 0.36648017 | J20: =J19-K2*U19 -> -0.63718531 | K20: =K19-K2*V19 -> 0.061565251 | L20: =L19-K2*W19 -> 0.30550813 | M20: =M19-K2*X19 -> 0.47258679 | N20: =I20+J20*C20+K20*D20+L20*E20+F20*M20 -> -2.3472921 | O20: =1/(1+EXP(-N20)) -> 0.087281254 | P20: =IF(O20>0.5,1,0) -> 0 | Q20: =O20-G20 -> 0.087281254 | R20: =Q20^2 -> 0.0076180173 | T20: =2*(O20-G20)*(1-O20)*O20 -> 0.013906214 | U20: =2*(O20-G20)*(1-O20)*O20*C20 -> 0.079265422 | V20: =2*(O20-G20)*(1-O20)*O20*D20 -> 0.061187343 | W20: =2*(O20-G20)*(1-O20)*O20*E20 -> 0.020859322 | X20: =2*(O20-G20)*(1-O20)*O20*F20 -> 0.0055624857
B21: 17 | C21: 5.4 | D21: 3.9 | E21: 1.3 | F21: 0.4 | G21: 0 | I21: =I20-K2*T20 -> 0.36508954 | J21: =J20-K2*U20 -> -0.64511185 | K21: =K20-K2*V20 -> 0.055446517 | L21: =L20-K2*W20 -> 0.3034222 | M21: =M20-K2*X20 -> 0.47203055 | N21: =I21+J21*C21+K21*D21+L21*E21+F21*M21 -> -2.319012 | O21: =1/(1+EXP(-N21)) -> 0.089560591 | P21: =IF(O21>0.5,1,0) -> 0 | Q21: =O21-G21 -> 0.089560591 | R21: =Q21^2 -> 0.0080210995 | T21: =2*(O21-G21)*(1-O21)*O21 -> 0.01460545 | U21: =2*(O21-G21)*(1-O21)*O21*C21 -> 0.078869431 | V21: =2*(O21-G21)*(1-O21)*O21*D21 -> 0.056961256 | W21: =2*(O21-G21)*(1-O21)*O21*E21 -> 0.018987085 | X21: =2*(O21-G21)*(1-O21)*O21*F21 -> 0.0058421801
B22: 18 | C22: 5.1 | D22: 3.5 | E22: 1.4 | F22: 0.3 | G22: 0 | I22: =I21-K2*T21 -> 0.363629 | J22: =J21-K2*U21 -> -0.65299879 | K22: =K21-K2*V21 -> 0.049750391 | L22: =L21-K2*W21 -> 0.30152349 | M22: =M21-K2*X21 -> 0.47144633 | N22: =I22+J22*C22+K22*D22+L22*E22+F22*M22 -> -2.2289717 | O22: =1/(1+EXP(-N22)) -> 0.097178822 | P22: =IF(O22>0.5,1,0) -> 0 | Q22: =O22-G22 -> 0.097178822 | R22: =Q22^2 -> 0.0094437235 | T22: =2*(O22-G22)*(1-O22)*O22 -> 0.017051987 | U22: =2*(O22-G22)*(1-O22)*O22*C22 -> 0.086965134 | V22: =2*(O22-G22)*(1-O22)*O22*D22 -> 0.059681955 | W22: =2*(O22-G22)*(1-O22)*O22*E22 -> 0.023872782 | X22: =2*(O22-G22)*(1-O22)*O22*F22 -> 0.0051155961
B23: 19 | C23: 5.7 | D23: 3.8 | E23: 1.7 | F23: 0.3 | G23: 0 | I23: =I22-K2*T22 -> 0.3619238 | J23: =J22-K2*U22 -> -0.66169531 | K23: =K22-K2*V22 -> 0.043782196 | L23: =L22-K2*W22 -> 0.29913621 | M23: =M22-K2*X22 -> 0.47093477 | N23: =I23+J23*C23+K23*D23+L23*E23+F23*M23 -> -2.5935551 | O23: =1/(1+EXP(-N23)) -> 0.069554356 | P23: =IF(O23>0.5,1,0) -> 0 | Q23: =O23-G23 -> 0.069554356 | R23: =Q23^2 -> 0.0048378084 | T23: =2*(O23-G23)*(1-O23)*O23 -> 0.0090026355 | U23: =2*(O23-G23)*(1-O23)*O23*C23 -> 0.051315023 | V23: =2*(O23-G23)*(1-O23)*O23*D23 -> 0.034210015 | W23: =2*(O23-G23)*(1-O23)*O23*E23 -> 0.01530448 | X23: =2*(O23-G23)*(1-O23)*O23*F23 -> 0.0027007907
B24: 20 | C24: 5.1 | D24: 3.8 | E24: 1.5 | F24: 0.3 | G24: 0 | I24: =I23-K2*T23 -> 0.36102354 | J24: =J23-K2*U23 -> -0.66682681 | K24: =K23-K2*V23 -> 0.040361194 | L24: =L23-K2*W23 -> 0.29760577 | M24: =M23-K2*X23 -> 0.47066469 | N24: =I24+J24*C24+K24*D24+L24*E24+F24*M24 -> -2.2988126 | O24: =1/(1+EXP(-N24)) -> 0.091221349 | P24: =IF(O24>0.5,1,0) -> 0 | Q24: =O24-G24 -> 0.091221349 | R24: =Q24^2 -> 0.0083213345 | T24: =2*(O24-G24)*(1-O24)*O24 -> 0.015124502 | U24: =2*(O24-G24)*(1-O24)*O24*C24 -> 0.077134962 | V24: =2*(O24-G24)*(1-O24)*O24*D24 -> 0.057473109 | W24: =2*(O24-G24)*(1-O24)*O24*E24 -> 0.022686753 | X24: =2*(O24-G24)*(1-O24)*O24*F24 -> 0.0045373507
B25: 21 | C25: 5.4 | D25: 3.4 | E25: 1.7 | F25: 0.2 | G25: 0 | I25: =I24-K2*T24 -> 0.35951109 | J25: =J24-K2*U24 -> -0.67454031 | K25: =K24-K2*V24 -> 0.034613883 | L25: =L24-K2*W24 -> 0.29533709 | M25: =M24-K2*X24 -> 0.47021095 | N25: =I25+J25*C25+K25*D25+L25*E25+F25*M25 -> -2.5692041 | O25: =1/(1+EXP(-N25)) -> 0.071146882 | P25: =IF(O25>0.5,1,0) -> 0 | Q25: =O25-G25 -> 0.071146882 | R25: =Q25^2 -> 0.0050618788 | T25: =2*(O25-G25)*(1-O25)*O25 -> 0.0094034839 | U25: =2*(O25-G25)*(1-O25)*O25*C25 -> 0.050778813 | V25: =2*(O25-G25)*(1-O25)*O25*D25 -> 0.031971845 | W25: =2*(O25-G25)*(1-O25)*O25*E25 -> 0.015985923 | X25: =2*(O25-G25)*(1-O25)*O25*F25 -> 0.0018806968
B26: 22 | C26: 5.1 | D26: 3.7 | E26: 1.5 | F26: 0.4 | G26: 0 | I26: =I25-K2*T25 -> 0.35857074 | J26: =J25-K2*U25 -> -0.67961819 | K26: =K25-K2*V25 -> 0.031416699 | L26: =L25-K2*W25 -> 0.2937385 | M26: =M25-K2*X25 -> 0.47002288 | N26: =I26+J26*C26+K26*D26+L26*E26+F26*M26 -> -2.3626233 | O26: =1/(1+EXP(-N26)) -> 0.086067619 | P26: =IF(O26>0.5,1,0) -> 0 | Q26: =O26-G26 -> 0.086067619 | R26: =Q26^2 -> 0.0074076351 | T26: =2*(O26-G26)*(1-O26)*O26 -> 0.013540155 | U26: =2*(O26-G26)*(1-O26)*O26*C26 -> 0.069054791 | V26: =2*(O26-G26)*(1-O26)*O26*D26 -> 0.050098574 | W26: =2*(O26-G26)*(1-O26)*O26*E26 -> 0.020310233 | X26: =2*(O26-G26)*(1-O26)*O26*F26 -> 0.0054160621
B27: 23 | C27: 4.6 | D27: 3.6 | E27: 1 | F27: 0.2 | G27: 0 | I27: =I26-K2*T26 -> 0.35721672 | J27: =J26-K2*U26 -> -0.68652367 | K27: =K26-K2*V26 -> 0.026406842 | L27: =L26-K2*W26 -> 0.29170748 | M27: =M26-K2*X26 -> 0.46948128 | N27: =I27+J27*C27+K27*D27+L27*E27+F27*M27 -> -2.3201238 | O27: =1/(1+EXP(-N27)) -> 0.089469975 | P27: =IF(O27>0.5,1,0) -> 0 | Q27: =O27-G27 -> 0.089469975 | R27: =Q27^2 -> 0.0080048764 | T27: =2*(O27-G27)*(1-O27)*O27 -> 0.014577361 | U27: =2*(O27-G27)*(1-O27)*O27*C27 -> 0.067055859 | V27: =2*(O27-G27)*(1-O27)*O27*D27 -> 0.052478498 | W27: =2*(O27-G27)*(1-O27)*O27*E27 -> 0.014577361 | X27: =2*(O27-G27)*(1-O27)*O27*F27 -> 0.0029154721
B28: 24 | C28: 5.1 | D28: 3.3 | E28: 1.7 | F28: 0.5 | G28: 0 | I28: =I27-K2*T27 -> 0.35575899 | J28: =J27-K2*U27 -> -0.69322925 | K28: =K27-K2*V27 -> 0.021158992 | L28: =L27-K2*W27 -> 0.29024974 | M28: =M27-K2*X27 -> 0.46918973 | N28: =I28+J28*C28+K28*D28+L28*E28+F28*M28 -> -2.3818661 | O28: =1/(1+EXP(-N28)) -> 0.08456599 | P28: =IF(O28>0.5,1,0) -> 0 | Q28: =O28-G28 -> 0.08456599 | R28: =Q28^2 -> 0.0071514067 | T28: =2*(O28-G28)*(1-O28)*O28 -> 0.013093282 | U28: =2*(O28-G28)*(1-O28)*O28*C28 -> 0.066775737 | V28: =2*(O28-G28)*(1-O28)*O28*D28 -> 0.04320783 | W28: =2*(O28-G28)*(1-O28)*O28*E28 -> 0.022258579 | X28: =2*(O28-G28)*(1-O28)*O28*F28 -> 0.0065466409
B29: 25 | C29: 4.8 | D29: 3.4 | E29: 1.9 | F29: 0.2 | G29: 0 | I29: =I28-K2*T28 -> 0.35444966 | J29: =J28-K2*U28 -> -0.69990683 | K29: =K28-K2*V28 -> 0.016838209 | L29: =L28-K2*W28 -> 0.28802388 | M29: =M28-K2*X28 -> 0.46853507 | N29: =I29+J29*C29+K29*D29+L29*E29+F29*M29 -> -2.3069008 | O29: =1/(1+EXP(-N29)) -> 0.090553049 | P29: =IF(O29>0.5,1,0) -> 0 | Q29: =O29-G29 -> 0.090553049 | R29: =Q29^2 -> 0.0081998548 | T29: =2*(O29-G29)*(1-O29)*O29 -> 0.014914666 | U29: =2*(O29-G29)*(1-O29)*O29*C29 -> 0.071590396 | V29: =2*(O29-G29)*(1-O29)*O29*D29 -> 0.050709864 | W29: =2*(O29-G29)*(1-O29)*O29*E29 -> 0.028337865 | X29: =2*(O29-G29)*(1-O29)*O29*F29 -> 0.0029829332
B30: 26 | C30: 5 | D30: 3 | E30: 1.6 | F30: 0.2 | G30: 0 | I30: =I29-K2*T29 -> 0.35295819 | J30: =J29-K2*U29 -> -0.70706587 | K30: =K29-K2*V29 -> 0.011767222 | L30: =L29-K2*W29 -> 0.2851901 | M30: =M29-K2*X29 -> 0.46823677 | N30: =I30+J30*C30+K30*D30+L30*E30+F30*M30 -> -2.597118 | O30: =1/(1+EXP(-N30)) -> 0.069324134 | P30: =IF(O30>0.5,1,0) -> 0 | Q30: =O30-G30 -> 0.069324134 | R30: =Q30^2 -> 0.0048058355 | T30: =2*(O30-G30)*(1-O30)*O30 -> 0.0089453503 | U30: =2*(O30-G30)*(1-O30)*O30*C30 -> 0.044726752 | V30: =2*(O30-G30)*(1-O30)*O30*D30 -> 0.026836051 | W30: =2*(O30-G30)*(1-O30)*O30*E30 -> 0.01431256 | X30: =2*(O30-G30)*(1-O30)*O30*F30 -> 0.0017890701
B31: 27 | C31: 5 | D31: 3.4 | E31: 1.6 | F31: 0.4 | G31: 0 | I31: =I30-K2*T30 -> 0.35206366 | J31: =J30-K2*U30 -> -0.71153854 | K31: =K30-K2*V30 -> 0.0090836172 | L31: =L30-K2*W30 -> 0.28375884 | M31: =M30-K2*X30 -> 0.46805787 | N31: =I31+J31*C31+K31*D31+L31*E31+F31*M31 -> -2.5335075 | O31: =1/(1+EXP(-N31)) -> 0.073542312 | P31: =IF(O31>0.5,1,0) -> 0 | Q31: =O31-G31 -> 0.073542312 | R31: =Q31^2 -> 0.0054084717 | T31: =2*(O31-G31)*(1-O31)*O31 -> 0.01002144 | U31: =2*(O31-G31)*(1-O31)*O31*C31 -> 0.050107202 | V31: =2*(O31-G31)*(1-O31)*O31*D31 -> 0.034072897 | W31: =2*(O31-G31)*(1-O31)*O31*E31 -> 0.016034305 | X31: =2*(O31-G31)*(1-O31)*O31*F31 -> 0.0040085761
B32: 28 | C32: 5.2 | D32: 3.5 | E32: 1.5 | F32: 0.2 | G32: 0 | I32: =I31-K2*T31 -> 0.35106151 | J32: =J31-K2*U31 -> -0.71654926 | K32: =K31-K2*V31 -> 0.0056763275 | L32: =L31-K2*W31 -> 0.28215541 | M32: =M31-K2*X31 -> 0.46765701 | N32: =I32+J32*C32+K32*D32+L32*E32+F32*M32 -> -2.838363 | O32: =1/(1+EXP(-N32)) -> 0.055285976 | P32: =IF(O32>0.5,1,0) -> 0 | Q32: =O32-G32 -> 0.055285976 | R32: =Q32^2 -> 0.0030565391 | T32: =2*(O32-G32)*(1-O32)*O32 -> 0.0057751108 | U32: =2*(O32-G32)*(1-O32)*O32*C32 -> 0.030030576 | V32: =2*(O32-G32)*(1-O32)*O32*D32 -> 0.020212888 | W32: =2*(O32-G32)*(1-O32)*O32*E32 -> 0.0086626662 | X32: =2*(O32-G32)*(1-O32)*O32*F32 -> 0.0011550222
B33: 29 | C33: 5.2 | D33: 3.4 | E33: 1.4 | F33: 0.2 | G33: 0 | I33: =I32-K2*T32 -> 0.350484 | J33: =J32-K2*U32 -> -0.71955232 | K33: =K32-K2*V32 -> 0.0036550387 | L33: =L32-K2*W32 -> 0.28128914 | M33: =M32-K2*X32 -> 0.46754151 | N33: =I33+J33*C33+K33*D33+L33*E33+F33*M33 -> -2.8914478 | O33: =1/(1+EXP(-N33)) -> 0.052577951 | P33: =IF(O33>0.5,1,0) -> 0 | Q33: =O33-G33 -> 0.052577951 | R33: =Q33^2 -> 0.0027644409 | T33: =2*(O33-G33)*(1-O33)*O33 -> 0.0052381845 | U33: =2*(O33-G33)*(1-O33)*O33*C33 -> 0.027238559 | V33: =2*(O33-G33)*(1-O33)*O33*D33 -> 0.017809827 | W33: =2*(O33-G33)*(1-O33)*O33*E33 -> 0.0073334583 | X33: =2*(O33-G33)*(1-O33)*O33*F33 -> 0.0010476369
B34: 30 | C34: 4.7 | D34: 3.2 | E34: 1.6 | F34: 0.2 | G34: 0 | I34: =I33-K2*T33 -> 0.34996018 | J34: =J33-K2*U33 -> -0.72227617 | K34: =K33-K2*V33 -> 0.001874056 | L34: =L33-K2*W33 -> 0.2805558 | M34: =M33-K2*X33 -> 0.46743674 | N34: =I34+J34*C34+K34*D34+L34*E34+F34*M34 -> -2.4963642 | O34: =1/(1+EXP(-N34)) -> 0.076113454 | P34: =IF(O34>0.5,1,0) -> 0 | Q34: =O34-G34 -> 0.076113454 | R34: =Q34^2 -> 0.0057932579 | T34: =2*(O34-G34)*(1-O34)*O34 -> 0.010704626 | U34: =2*(O34-G34)*(1-O34)*O34*C34 -> 0.050311742 | V34: =2*(O34-G34)*(1-O34)*O34*D34 -> 0.034254803 | W34: =2*(O34-G34)*(1-O34)*O34*E34 -> 0.017127402 | X34: =2*(O34-G34)*(1-O34)*O34*F34 -> 0.0021409252
B35: 31 | C35: 4.8 | D35: 3.1 | E35: 1.6 | F35: 0.2 | G35: 0 | I35: =I34-K2*T34 -> 0.34888972 | J35: =J34-K2*U34 -> -0.72730735 | K35: =K34-K2*V34 -> -0.0015514243 | L35: =L34-K2*W34 -> 0.27884306 | M35: =M34-K2*X34 -> 0.46722265 | N35: =I35+J35*C35+K35*D35+L35*E35+F35*M35 -> -2.6074015 | O35: =1/(1+EXP(-N35)) -> 0.068663586 | P35: =IF(O35>0.5,1,0) -> 0 | Q35: =O35-G35 -> 0.068663586 | R35: =Q35^2 -> 0.004714688 | T35: =2*(O35-G35)*(1-O35)*O35 -> 0.0087819212 | U35: =2*(O35-G35)*(1-O35)*O35*C35 -> 0.042153222 | V35: =2*(O35-G35)*(1-O35)*O35*D35 -> 0.027223956 | W35: =2*(O35-G35)*(1-O35)*O35*E35 -> 0.014051074 | X35: =2*(O35-G35)*(1-O35)*O35*F35 -> 0.0017563842
B36: 32 | C36: 5.4 | D36: 3.4 | E36: 1.5 | F36: 0.4 | G36: 0 | I36: =I35-K2*T35 -> 0.34801153 | J36: =J35-K2*U35 -> -0.73152267 | K36: =K35-K2*V35 -> -0.0042738199 | L36: =L35-K2*W35 -> 0.27743795 | M36: =M35-K2*X35 -> 0.46704701 | N36: =I36+J36*C36+K36*D36+L36*E36+F36*M36 -> -3.0137662 | O36: =1/(1+EXP(-N36)) -> 0.046807825 | P36: =IF(O36>0.5,1,0) -> 0 | Q36: =O36-G36 -> 0.046807825 | R36: =Q36^2 -> 0.0021909724 | T36: =2*(O36-G36)*(1-O36)*O36 -> 0.0041768356 | U36: =2*(O36-G36)*(1-O36)*O36*C36 -> 0.022554912 | V36: =2*(O36-G36)*(1-O36)*O36*D36 -> 0.014201241 | W36: =2*(O36-G36)*(1-O36)*O36*E36 -> 0.0062652534 | X36: =2*(O36-G36)*(1-O36)*O36*F36 -> 0.0016707342
B37: 33 | C37: 5.2 | D37: 4.1 | E37: 1.5 | F37: 0.1 | G37: 0 | I37: =I36-K2*T36 -> 0.34759385 | J37: =J36-K2*U36 -> -0.73377816 | K37: =K36-K2*V36 -> -0.005693944 | L37: =L36-K2*W36 -> 0.27681142 | M37: =M36-K2*X36 -> 0.46687994 | N37: =I37+J37*C37+K37*D37+L37*E37+F37*M37 -> -3.0294926 | O37: =1/(1+EXP(-N37)) -> 0.046111138 | P37: =IF(O37>0.5,1,0) -> 0 | Q37: =O37-G37 -> 0.046111138 | R37: =Q37^2 -> 0.0021262371 | T37: =2*(O37-G37)*(1-O37)*O37 -> 0.0040563877 | U37: =2*(O37-G37)*(1-O37)*O37*C37 -> 0.021093216 | V37: =2*(O37-G37)*(1-O37)*O37*D37 -> 0.01663119 | W37: =2*(O37-G37)*(1-O37)*O37*E37 -> 0.0060845815 | X37: =2*(O37-G37)*(1-O37)*O37*F37 -> 0.00040563877
B38: 34 | C38: 5.5 | D38: 4.2 | E38: 1.4 | F38: 0.2 | G38: 0 | I38: =I37-K2*T37 -> 0.34718821 | J38: =J37-K2*U37 -> -0.73588748 | K38: =K37-K2*V37 -> -0.007357063 | L38: =L37-K2*W37 -> 0.27620296 | M38: =M37-K2*X37 -> 0.46683937 | N38: =I38+J38*C38+K38*D38+L38*E38+F38*M38 -> -3.2510406 | O38: =1/(1+EXP(-N38)) -> 0.037289513 | P38: =IF(O38>0.5,1,0) -> 0 | Q38: =O38-G38 -> 0.037289513 | R38: =Q38^2 -> 0.0013905078 | T38: =2*(O38-G38)*(1-O38)*O38 -> 0.0026773129 | U38: =2*(O38-G38)*(1-O38)*O38*C38 -> 0.014725221 | V38: =2*(O38-G38)*(1-O38)*O38*D38 -> 0.011244714 | W38: =2*(O38-G38)*(1-O38)*O38*E38 -> 0.003748238 | X38: =2*(O38-G38)*(1-O38)*O38*F38 -> 0.00053546257
B39: 35 | C39: 4.9 | D39: 3.1 | E39: 1.5 | F39: 0.1 | G39: 0 | I39: =I38-K2*T38 -> 0.34692048 | J39: =J38-K2*U38 -> -0.73736001 | K39: =K38-K2*V38 -> -0.0084815344 | L39: =L38-K2*W38 -> 0.27582814 | M39: =M38-K2*X38 -> 0.46678583 | N39: =I39+J39*C39+K39*D39+L39*E39+F39*M39 -> -2.8320155 | O39: =1/(1+EXP(-N39)) -> 0.055618438 | P39: =IF(O39>0.5,1,0) -> 0 | Q39: =O39-G39 -> 0.055618438 | R39: =Q39^2 -> 0.0030934107 | T39: =2*(O39-G39)*(1-O39)*O39 -> 0.00584272 | U39: =2*(O39-G39)*(1-O39)*O39*C39 -> 0.028629328 | V39: =2*(O39-G39)*(1-O39)*O39*D39 -> 0.018112432 | W39: =2*(O39-G39)*(1-O39)*O39*E39 -> 0.00876408 | X39: =2*(O39-G39)*(1-O39)*O39*F39 -> 0.000584272
B40: 36 | C40: 5 | D40: 3.2 | E40: 1.2 | F40: 0.2 | G40: 0 | I40: =I39-K2*T39 -> 0.3463362 | J40: =J39-K2*U39 -> -0.74022294 | K40: =K39-K2*V39 -> -0.010292778 | L40: =L39-K2*W39 -> 0.27495173 | M40: =M39-K2*X39 -> 0.4667274 | N40: =I40+J40*C40+K40*D40+L40*E40+F40*M40 -> -2.9644278 | O40: =1/(1+EXP(-N40)) -> 0.049059026 | P40: =IF(O40>0.5,1,0) -> 0 | Q40: =O40-G40 -> 0.049059026 | R40: =Q40^2 -> 0.002406788 | T40: =2*(O40-G40)*(1-O40)*O40 -> 0.0045774266 | U40: =2*(O40-G40)*(1-O40)*O40*C40 -> 0.022887133 | V40: =2*(O40-G40)*(1-O40)*O40*D40 -> 0.014647765 | W40: =2*(O40-G40)*(1-O40)*O40*E40 -> 0.005492912 | X40: =2*(O40-G40)*(1-O40)*O40*F40 -> 0.00091548533
B41: 37 | C41: 5.5 | D41: 3.5 | E41: 1.3 | F41: 0.2 | G41: 0 | I41: =I40-K2*T40 -> 0.34587846 | J41: =J40-K2*U40 -> -0.74251165 | K41: =K40-K2*V40 -> -0.011757554 | L41: =L40-K2*W40 -> 0.27440244 | M41: =M40-K2*X40 -> 0.46663585 | N41: =I41+J41*C41+K41*D41+L41*E41+F41*M41 -> -3.3290367 | O41: =1/(1+EXP(-N41)) -> 0.034588382 | P41: =IF(O41>0.5,1,0) -> 0 | Q41: =O41-G41 -> 0.034588382 | R41: =Q41^2 -> 0.0011963562 | T41: =2*(O41-G41)*(1-O41)*O41 -> 0.0023099523 | U41: =2*(O41-G41)*(1-O41)*O41*C41 -> 0.012704737 | V41: =2*(O41-G41)*(1-O41)*O41*D41 -> 0.0080848329 | W41: =2*(O41-G41)*(1-O41)*O41*E41 -> 0.0030029379 | X41: =2*(O41-G41)*(1-O41)*O41*F41 -> 0.00046199045
...

Sheet SLP-Validation
I2: in validation, bias and teta are obtained from training for each epoch | AF2: Epoch | AG2: MSE | AH2: MSE(Val)
Z3: Epoch | AA3: MSE (Val) | AB3: Accuracy (Val) | AF3: 1 | AG3: 0.1299649 | AH3: 0.090967615
G4: Setosa = 0 | I4: Learning Rate | K4: 0.1 | W4: 0 | Z4: 1 | AA4: =S26 -> 0.090967615 | AB4: =H26 -> 0.85 | AF4: 2 | AG4: 0.034548306 | AH4: 0.060245072
G5: Versicolor = 1 | H5: Accuracy | I5: Bobot bias | N5: dot product | O5: Sigmoid | P5: Prediksi | Q5: error | R5: Sum Square Error | S5: MSE (avg) | Z5: 2 | AA5: =S46 -> 0.060245072 | AB5: =H46 -> 0.95 | AF5: 3 | AG5: 0.022989957 | AH5: 0.042968768
A6: EPOCH | B6: No | C6: X1 | D6: X2 | E6: X3 | F6: X4 | G6: TARGET | I6: bias | J6: teta1 | K6: teta2 | L6: teta 3 | M6: teta4 | N6: z | O6: g(z) | Z6: 3 | AA6: =S66 -> 0.042968768 | AB6: =H66 -> 0.95 | AF6: 4 | AG6: 0.016535227 | AH6: 0.032918119
A7: epoch1 | B7: 1 | C7: 5 | D7: 3.5 | E7: 1.3 | F7: 0.3 | G7: 0 | I7: ='SLP-Training'!I84-'SLP-Training'!$K$2*'SLP-Training'!T84 -> 0.4294974 | J7: ='SLP-Training'!J84-'SLP-Training'!$K$2*'SLP-Training'!U84 -> -0.2042125 | K7: ='SLP-Training'!K84-'SLP-Training'!$K$2*'SLP-Training'!V84 -> 0.23458013 | L7: ='SLP-Training'!L84-'SLP-Training'!$K$2*'SLP-Training'!W84 -> 0.65708429 | M7: ='SLP-Training'!M84-'SLP-Training'!$K$2*'SLP-Training'!X84 -> 0.58649398 | N7: =I7+J7*C7+K7*D7+L7*E7+F7*M7 -> 1.2596231 | O7: =1/(1+EXP(-N7)) -> 0.77896122 | P7: =IF(O7>0.5,1,0) -> 1 | Q7: =O7-G7 -> 0.77896122 | R7: =Q7^2 -> 0.60678059 | T7: =2*(O7-G7)*(1-O7)*O7 -> 0.26824408 | U7: =2*(O7-G7)*(1-O7)*O7*C7 -> 1.3412204 | V7: =2*(O7-G7)*(1-O7)*O7*D7 -> 0.93885427 | W7: =2*(O7-G7)*(1-O7)*O7*E7 -> 0.3487173 | X7: =2*(O7-G7)*(1-O7)*O7*F7 -> 0.080473223 | Z7: 4 | AA7: =S86 -> 0.032918119 | AB7: =H86 -> 1 | AF7: 5 | AG7: 0.012222388 | AH7: 0.026561283
B8: 2 | C8: 4.5 | D8: 2.3 | E8: 1.3 | F8: 0.3 | G8: 0 | I8: =I7-K4*T7 -> 0.40267299 | J8: =J7-K4*U7 -> -0.33833454 | K8: =K7-K4*V7 -> 0.14069471 | L8: =L7-K4*W7 -> 0.62221256 | M8: =M7-K4*X7 -> 0.57844665 | N8: =I8+J8*C8+K8*D8+L8*E8+F8*M8 -> 0.18617571 | O8: =1/(1+EXP(-N8)) -> 0.54640995 | P8: =IF(O8>0.5,1,0) -> 1 | Q8: =O8-G8 -> 0.54640995 | R8: =Q8^2 -> 0.29856384 | T8: =2*(O8-G8)*(1-O8)*O8 -> 0.27085117 | U8: =2*(O8-G8)*(1-O8)*O8*C8 -> 1.2188303 | V8: =2*(O8-G8)*(1-O8)*O8*D8 -> 0.62295769 | W8: =2*(O8-G8)*(1-O8)*O8*E8 -> 0.35210652 | X8: =2*(O8-G8)*(1-O8)*O8*F8 -> 0.081255351 | Z8: 5 | AA8: =S106 -> 0.026561283 | AB8: =H106 -> 1
B9: 3 | C9: 4.4 | D9: 3.2 | E9: 1.3 | F9: 0.2 | G9: 0 | I9: =I8-K4*T8 -> 0.37558788 | J9: =J8-K4*U8 -> -0.46021757 | K9: =K8-K4*V8 -> 0.078398936 | L9: =L8-K4*W8 -> 0.58700191 | M9: =M8-K4*X8 -> 0.57032112 | N9: =I9+J9*C9+K9*D9+L9*E9+F9*M9 -> -0.52132611 | O9: =1/(1+EXP(-N9)) -> 0.3725422 | P9: =IF(O9>0.5,1,0) -> 0 | Q9: =O9-G9 -> 0.3725422 | R9: =Q9^2 -> 0.13878769 | T9: =2*(O9-G9)*(1-O9)*O9 -> 0.17416684 | U9: =2*(O9-G9)*(1-O9)*O9*C9 -> 0.76633408 | V9: =2*(O9-G9)*(1-O9)*O9*D9 -> 0.55733387 | W9: =2*(O9-G9)*(1-O9)*O9*E9 -> 0.22641689 | X9: =2*(O9-G9)*(1-O9)*O9*F9 -> 0.034833367
B10: 4 | C10: 5 | D10: 3.5 | E10: 1.6 | F10: 0.6 | G10: 0 | I10: =I9-K4*T9 -> 0.35817119 | J10: =J9-K4*U9 -> -0.53685097 | K10: =K9-K4*V9 -> 0.022665549 | L10: =L9-K4*W9 -> 0.56436022 | M10: =M9-K4*X9 -> 0.56683778 | N10: =I10+J10*C10+K10*D10+L10*E10+F10*M10 -> -1.0036752 | O10: =1/(1+EXP(-N10)) -> 0.26821944 | P10: =IF(O10>0.5,1,0) -> 0 | Q10: =O10-G10 -> 0.26821944 | R10: =Q10^2 -> 0.071941668 | T10: =2*(O10-G10)*(1-O10)*O10 -> 0.10529103 | U10: =2*(O10-G10)*(1-O10)*O10*C10 -> 0.52645514 | V10: =2*(O10-G10)*(1-O10)*O10*D10 -> 0.3685186 | W10: =2*(O10-G10)*(1-O10)*O10*E10 -> 0.16846565 | X10: =2*(O10-G10)*(1-O10)*O10*F10 -> 0.063174617
B11: 5 | C11: 5.1 | D11: 3.8 | E11: 1.9 | F11: 0.4 | G11: 0 | I11: =I10-K4*T10 -> 0.34764209 | J11: =J10-K4*U10 -> -0.58949649 | K11: =K10-K4*V10 -> -0.014186311 | L11: =L10-K4*W10 -> 0.54751366 | M11: =M10-K4*X10 -> 0.56052032 | N11: =I11+J11*C11+K11*D11+L11*E11+F11*M11 -> -1.4482139 | O11: =1/(1+EXP(-N11)) -> 0.1902766 | P11: =IF(O11>0.5,1,0) -> 0 | Q11: =O11-G11 -> 0.1902766 | R11: =Q11^2 -> 0.036205184 | T11: =2*(O11-G11)*(1-O11)*O11 -> 0.05863237 | U11: =2*(O11-G11)*(1-O11)*O11*C11 -> 0.29902509 | V11: =2*(O11-G11)*(1-O11)*O11*D11 -> 0.22280301 | W11: =2*(O11-G11)*(1-O11)*O11*E11 -> 0.1114015 | X11: =2*(O11-G11)*(1-O11)*O11*F11 -> 0.023452948
B12: 6 | C12: 4.8 | D12: 3 | E12: 1.4 | F12: 0.3 | G12: 0 | I12: =I11-K4*T11 -> 0.34177885 | J12: =J11-K4*U11 -> -0.619399 | K12: =K11-K4*V11 -> -0.036466612 | L12: =L11-K4*W11 -> 0.53637351 | M12: =M11-K4*X11 -> 0.55817503 | N12: =I12+J12*C12+K12*D12+L12*E12+F12*M12 -> -1.8223608 | O12: =1/(1+EXP(-N12)) -> 0.13915084 | P12: =IF(O12>0.5,1,0) -> 0 | Q12: =O12-G12 -> 0.13915084 | R12: =Q12^2 -> 0.019362957 | T12: =2*(O12-G12)*(1-O12)*O12 -> 0.03333717 | U12: =2*(O12-G12)*(1-O12)*O12*C12 -> 0.16001842 | V12: =2*(O12-G12)*(1-O12)*O12*D12 -> 0.10001151 | W12: =2*(O12-G12)*(1-O12)*O12*E12 -> 0.046672039 | X12: =2*(O12-G12)*(1-O12)*O12*F12 -> 0.010001151
B13: 7 | C13: 5.1 | D13: 3.8 | E13: 1.6 | F13: 0.2 | G13: 0 | I13: =I12-K4*T12 -> 0.33844514 | J13: =J12-K4*U12 -> -0.63540084 | K13: =K12-K4*V12 -> -0.046467763 | L13: =L12-K4*W12 -> 0.5317063 | M13: =M12-K4*X12 -> 0.55717491 | N13: =I13+J13*C13+K13*D13+L13*E13+F13*M13 -> -2.1165116 | O13: =1/(1+EXP(-N13)) -> 0.10750231 | P13: =IF(O13>0.5,1,0) -> 0 | Q13: =O13-G13 -> 0.10750231 | R13: =Q13^2 -> 0.011556747 | T13: =2*(O13-G13)*(1-O13)*O13 -> 0.02062874 | U13: =2*(O13-G13)*(1-O13)*O13*C13 -> 0.10520657 | V13: =2*(O13-G13)*(1-O13)*O13*D13 -> 0.078389212 | W13: =2*(O13-G13)*(1-O13)*O13*E13 -> 0.033005984 | X13: =2*(O13-G13)*(1-O13)*O13*F13 -> 0.004125748
B14: 8 | C14: 4.6 | D14: 3.2 | E14: 1.4 | F14: 0.2 | G14: 0 | I14: =I13-K4*T13 -> 0.33638226 | J14: =J13-K4*U13 -> -0.6459215 | K14: =K13-K4*V13 -> -0.054306684 | L14: =L13-K4*W13 -> 0.5284057 | M14: =M13-K4*X13 -> 0.55676234 | N14: =I14+J14*C14+K14*D14+L14*E14+F14*M14 -> -1.9575176 | O14: =1/(1+EXP(-N14)) -> 0.12373596 | P14: =IF(O14>0.5,1,0) -> 0 | Q14: =O14-G14 -> 0.12373596 | R14: =Q14^2 -> 0.015310587 | T14: =2*(O14-G14)*(1-O14)*O14 -> 0.026832233 | U14: =2*(O14-G14)*(1-O14)*O14*C14 -> 0.12342827 | V14: =2*(O14-G14)*(1-O14)*O14*D14 -> 0.085863147 | W14: =2*(O14-G14)*(1-O14)*O14*E14 -> 0.037565127 | X14: =2*(O14-G14)*(1-O14)*O14*F14 -> 0.0053664467
B15: 9 | C15: 5.3 | D15: 3.7 | E15: 1.5 | F15: 0.2 | G15: 0 | I15: =I14-K4*T14 -> 0.33369904 | J15: =J14-K4*U14 -> -0.65826432 | K15: =K14-K4*V14 -> -0.062892999 | L15: =L14-K4*W14 -> 0.52464919 | M15: =M14-K4*X14 -> 0.55622569 | N15: =I15+J15*C15+K15*D15+L15*E15+F15*M15 -> -2.489587 | O15: =1/(1+EXP(-N15)) -> 0.076591398 | P15: =IF(O15>0.5,1,0) -> 0 | Q15: =O15-G15 -> 0.076591398 | R15: =Q15^2 -> 0.0058662423 | T15: =2*(O15-G15)*(1-O15)*O15 -> 0.010833877 | U15: =2*(O15-G15)*(1-O15)*O15*C15 -> 0.057419549 | V15: =2*(O15-G15)*(1-O15)*O15*D15 -> 0.040085346 | W15: =2*(O15-G15)*(1-O15)*O15*E15 -> 0.016250816 | X15: =2*(O15-G15)*(1-O15)*O15*F15 -> 0.0021667754
B16: 10 | C16: 5 | D16: 3.3 | E16: 1.4 | F16: 0.2 | G16: 0 | I16: =I15-K4*T15 -> 0.33261565 | J16: =J15-K4*U15 -> -0.66400628 | K16: =K15-K4*V15 -> -0.066901533 | L16: =L15-K4*W15 -> 0.52302411 | M16: =M15-K4*X15 -> 0.55600901 | N16: =I16+J16*C16+K16*D16+L16*E16+F16*M16 -> -2.3647552 | O16: =1/(1+EXP(-N16)) -> 0.085900071 | P16: =IF(O16>0.5,1,0) -> 0 | Q16: =O16-G16 -> 0.085900071 | R16: =Q16^2 -> 0.0073788221 | T16: =2*(O16-G16)*(1-O16)*O16 -> 0.013489962 | U16: =2*(O16-G16)*(1-O16)*O16*C16 -> 0.067449808 | V16: =2*(O16-G16)*(1-O16)*O16*D16 -> 0.044516873 | W16: =2*(O16-G16)*(1-O16)*O16*E16 -> 0.018885946 | X16: =2*(O16-G16)*(1-O16)*O16*F16 -> 0.0026979923
B17: 11 | C17: 5.5 | D17: 2.6 | E17: 4.4 | F17: 1.2 | G17: 1 | I17: =I16-K4*T16 -> 0.33126666 | J17: =J16-K4*U16 -> -0.67075126 | K17: =K16-K4*V16 -> -0.07135322 | L17: =L16-K4*W16 -> 0.52113552 | M17: =M16-K4*X16 -> 0.55573921 | N17: =I17+J17*C17+K17*D17+L17*E17+F17*M17 -> -0.58350032 | O17: =1/(1+EXP(-N17)) -> 0.35812757 | P17: =IF(O17>0.5,1,0) -> 0 | Q17: =O17-G17 -> -0.64187243 | R17: =Q17^2 -> 0.41200022 | T17: =2*(O17-G17)*(1-O17)*O17 -> -0.29509727 | U17: =2*(O17-G17)*(1-O17)*O17*C17 -> -1.623035 | V17: =2*(O17-G17)*(1-O17)*O17*D17 -> -0.76725291 | W17: =2*(O17-G17)*(1-O17)*O17*E17 -> -1.298428 | X17: =2*(O17-G17)*(1-O17)*O17*F17 -> -0.35411673
B18: 12 | C18: 6.1 | D18: 3 | E18: 4.6 | F18: 1.4 | G18: 1 | I18: =I17-K4*T17 -> 0.36077638 | J18: =J17-K4*U17 -> -0.50844776 | K18: =K17-K4*V17 -> 0.0053720704 | L18: =L17-K4*W17 -> 0.65097832 | M18: =M17-K4*X17 -> 0.59115089 | N18: =I18+J18*C18+K18*D18+L18*E18+F18*M18 -> 1.0974728 | O18: =1/(1+EXP(-N18)) -> 0.74978628 | P18: =IF(O18>0.5,1,0) -> 1 | Q18: =O18-G18 -> -0.25021372 | R18: =Q18^2 -> 0.062606908 | T18: =2*(O18-G18)*(1-O18)*O18 -> -0.0938836 | U18: =2*(O18-G18)*(1-O18)*O18*C18 -> -0.57268996 | V18: =2*(O18-G18)*(1-O18)*O18*D18 -> -0.2816508 | W18: =2*(O18-G18)*(1-O18)*O18*E18 -> -0.43186456 | X18: =2*(O18-G18)*(1-O18)*O18*F18 -> -0.13143704
B19: 13 | C19: 5.8 | D19: 2.6 | E19: 4 | F19: 1.2 | G19: 1 | I19: =I18-K4*T18 -> 0.37016474 | J19: =J18-K4*U18 -> -0.45117876 | K19: =K18-K4*V18 -> 0.033537151 | L19: =L18-K4*W18 -> 0.69416477 | M19: =M18-K4*X18 -> 0.60429459 | N19: =I19+J19*C19+K19*D19+L19*E19+F19*M19 -> 1.3423371 | O19: =1/(1+EXP(-N19)) -> 0.79287401 | P19: =IF(O19>0.5,1,0) -> 1 | Q19: =O19-G19 -> -0.20712599 | R19: =Q19^2 -> 0.042901174 | T19: =2*(O19-G19)*(1-O19)*O19 -> -0.068030452 | U19: =2*(O19-G19)*(1-O19)*O19*C19 -> -0.39457662 | V19: =2*(O19-G19)*(1-O19)*O19*D19 -> -0.17687918 | W19: =2*(O19-G19)*(1-O19)*O19*E19 -> -0.27212181 | X19: =2*(O19-G19)*(1-O19)*O19*F19 -> -0.081636543
B20: 14 | C20: 5 | D20: 2.3 | E20: 3.3 | F20: 1 | G20: 1 | I20: =I19-K4*T19 -> 0.37696779 | J20: =J19-K4*U19 -> -0.4117211 | K20: =K19-K4*V19 -> 0.051225068 | L20: =L19-K4*W19 -> 0.72137695 | M20: =M19-K4*X19 -> 0.61245824 | N20: =I20+J20*C20+K20*D20+L20*E20+F20*M20 -> 1.4291821 | O20: =1/(1+EXP(-N20)) -> 0.80677385 | P20: =IF(O20>0.5,1,0) -> 1 | Q20: =O20-G20 -> -0.19322615 | R20: =Q20^2 -> 0.037336345 | T20: =2*(O20-G20)*(1-O20)*O20 -> -0.060243974 | U20: =2*(O20-G20)*(1-O20)*O20*C20 -> -0.30121987 | V20: =2*(O20-G20)*(1-O20)*O20*D20 -> -0.13856114 | W20: =2*(O20-G20)*(1-O20)*O20*E20 -> -0.19880511 | X20: =2*(O20-G20)*(1-O20)*O20*F20 -> -0.060243974
B21: 15 | C21: 5.6 | D21: 2.7 | E21: 4.2 | F21: 1.3 | G21: 1 | I21: =I20-K4*T20 -> 0.38299219 | J21: =J20-K4*U20 -> -0.38159911 | K21: =K20-K4*V20 -> 0.065081182 | L21: =L20-K4*W20 -> 0.74125746 | M21: =M20-K4*X20 -> 0.61848264 | N21: =I21+J21*C21+K21*D21+L21*E21+F21*M21 -> 2.3390651 | O21: =1/(1+EXP(-N21)) -> 0.91206113 | P21: =IF(O21>0.5,1,0) -> 1 | Q21: =O21-G21 -> -0.087938869 | R21: =Q21^2 -> 0.0077332446 | T21: =2*(O21-G21)*(1-O21)*O21 -> -0.014106384 | U21: =2*(O21-G21)*(1-O21)*O21*C21 -> -0.078995748 | V21: =2*(O21-G21)*(1-O21)*O21*D21 -> -0.038087236 | W21: =2*(O21-G21)*(1-O21)*O21*E21 -> -0.059246811 | X21: =2*(O21-G21)*(1-O21)*O21*F21 -> -0.018338299
B22: 16 | C22: 5.7 | D22: 3 | E22: 4.2 | F22: 1.2 | G22: 1 | I22: =I21-K4*T21 -> 0.38440282 | J22: =J21-K4*U21 -> -0.37369954 | K22: =K21-K4*V21 -> 0.068889906 | L22: =L21-K4*W21 -> 0.74718214 | M22: =M21-K4*X21 -> 0.62031647 | N22: =I22+J22*C22+K22*D22+L22*E22+F22*M22 -> 2.3435299 | O22: =1/(1+EXP(-N22)) -> 0.91241858 | P22: =IF(O22>0.5,1,0) -> 1 | Q22: =O22-G22 -> -0.087581423 | R22: =Q22^2 -> 0.0076705057 | T22: =2*(O22-G22)*(1-O22)*O22 -> -0.013997424 | U22: =2*(O22-G22)*(1-O22)*O22*C22 -> -0.079785315 | V22: =2*(O22-G22)*(1-O22)*O22*D22 -> -0.041992271 | W22: =2*(O22-G22)*(1-O22)*O22*E22 -> -0.05878918 | X22: =2*(O22-G22)*(1-O22)*O22*F22 -> -0.016796908
B23: 17 | C23: 5.7 | D23: 2.9 | E23: 4.2 | F23: 1.3 | G23: 1 | I23: =I22-K4*T22 -> 0.38580257 | J23: =J22-K4*U22 -> -0.36572101 | K23: =K22-K4*V22 -> 0.073089133 | L23: =L22-K4*W22 -> 0.75306106 | M23: =M22-K4*X22 -> 0.62199616 | N23: =I23+J23*C23+K23*D23+L23*E23+F23*M23 -> 2.4846028 | O23: =1/(1+EXP(-N23)) -> 0.92305534 | P23: =IF(O23>0.5,1,0) -> 1 | Q23: =O23-G23 -> -0.076944656 | R23: =Q23^2 -> 0.0059204801 | T23: =2*(O23-G23)*(1-O23)*O23 -> -0.010929862 | U23: =2*(O23-G23)*(1-O23)*O23*C23 -> -0.062300211 | V23: =2*(O23-G23)*(1-O23)*O23*D23 -> -0.031696599 | W23: =2*(O23-G23)*(1-O23)*O23*E23 -> -0.045905419 | X23: =2*(O23-G23)*(1-O23)*O23*F23 -> -0.01420882
B24: 18 | C24: 6.2 | D24: 2.9 | E24: 4.3 | F24: 1.3 | G24: 1 | I24: =I23-K4*T23 -> 0.38689555 | J24: =J23-K4*U23 -> -0.35949099 | K24: =K23-K4*V23 -> 0.076258793 | L24: =L23-K4*W23 -> 0.7576516 | M24: =M23-K4*X23 -> 0.62341704 | N24: =I24+J24*C24+K24*D24+L24*E24+F24*M24 -> 2.447546 | O24: =1/(1+EXP(-N24)) -> 0.92038181 | P24: =IF(O24>0.5,1,0) -> 1 | Q24: =O24-G24 -> -0.079618191 | R24: =Q24^2 -> 0.0063390564 | T24: =2*(O24-G24)*(1-O24)*O24 -> -0.011668704 | U24: =2*(O24-G24)*(1-O24)*O24*C24 -> -0.072345967 | V24: =2*(O24-G24)*(1-O24)*O24*D24 -> -0.033839243 | W24: =2*(O24-G24)*(1-O24)*O24*E24 -> -0.050175429 | X24: =2*(O24-G24)*(1-O24)*O24*F24 -> -0.015169316
B25: 19 | C25: 5.1 | D25: 2.5 | E25: 3 | F25: 1.1 | G25: 1 | I25: =I24-K4*T24 -> 0.38806242 | J25: =J24-K4*U24 -> -0.35225639 | K25: =K24-K4*V24 -> 0.079642717 | L25: =L24-K4*W24 -> 0.76266915 | M25: =M24-K4*X24 -> 0.62493398 | N25: =I25+J25*C25+K25*D25+L25*E25+F25*M25 -> 1.7660964 | O25: =1/(1+EXP(-N25)) -> 0.85397155 | P25: =IF(O25>0.5,1,0) -> 1 | Q25: =O25-G25 -> -0.14602845 | R25: =Q25^2 -> 0.021324307 | T25: =2*(O25-G25)*(1-O25)*O25 -> -0.036420703 | U25: =2*(O25-G25)*(1-O25)*O25*C25 -> -0.18574559 | V25: =2*(O25-G25)*(1-O25)*O25*D25 -> -0.091051759 | W25: =2*(O25-G25)*(1-O25)*O25*E25 -> -0.10926211 | X25: =2*(O25-G25)*(1-O25)*O25*F25 -> -0.040062774
B26: 20 | C26: 5.7 | D26: 2.8 | E26: 4.1 | F26: 1.3 | G26: 1 | H26: =SUMPRODUCT(--(P7:P26=G7:G26))/20 -> 0.85 | I26: =I25-K4*T25 -> 0.39170449 | J26: =J25-K4*U25 -> -0.33368183 | K26: =K25-K4*V25 -> 0.088747893 | L26: =L25-K4*W25 -> 0.77359536 | M26: =M25-K4*X25 -> 0.62894025 | N26: =I26+J26*C26+K26*D26+L26*E26+F26*M26 -> 2.7275755 | O26: =1/(1+EXP(-N26)) -> 0.93863433 | P26: =IF(O26>0.5,1,0) -> 1 | Q26: =O26-G26 -> -0.061365668 | R26: =Q26^2 -> 0.0037657452 | S26: =AVERAGE(R7:R26) -> 0.090967615 | T26: =2*(O26-G26)*(1-O26)*O26 -> -0.0070693155 | U26: =2*(O26-G26)*(1-O26)*O26*C26 -> -0.040295098 | V26: =2*(O26-G26)*(1-O26)*O26*D26 -> -0.019794083 | W26: =2*(O26-G26)*(1-O26)*O26*E26 -> -0.028984193 | X26: =2*(O26-G26)*(1-O26)*O26*F26 -> -0.0091901101
A27: epoch 2 | B27: 1 | C27: 5 | D27: 3.5 | E27: 1.3 | F27: 0.3 | G27: 0 | I27: ='SLP-Training'!I164-'SLP-Training'!$K$2*'SLP-Training'!T164 -> 0.3931413 | J27: ='SLP-Training'!J164-'SLP-Training'!$K$2*'SLP-Training'!U164 -> -0.27405986 | K27: ='SLP-Training'!K164-'SLP-Training'!$K$2*'SLP-Training'!V164 -> 0.090895772 | L27: ='SLP-Training'!L164-'SLP-Training'!$K$2*'SLP-Training'!W164 -> 0.83580129 | M27: ='SLP-Training'!M164-'SLP-Training'!$K$2*'SLP-Training'!X164 -> 0.66970416 | N27: =I27+J27*C27+K27*D27+L27*E27+F27*M27 -> 0.62843012 | O27: =1/(1+EXP(-N27)) -> 0.65213341 | P27: =IF(O27>0.5,1,0) -> 1 | Q27: =O27-G27 -> 0.65213341 | R27: =Q27^2 -> 0.42527799 | T27: =2*(O27-G27)*(1-O27)*O27 -> 0.29588 | U27: =2*(O27-G27)*(1-O27)*O27*C27 -> 1.4794 | V27: =2*(O27-G27)*(1-O27)*O27*D27 -> 1.03558 | W27: =2*(O27-G27)*(1-O27)*O27*E27 -> 0.38464401 | X27: =2*(O27-G27)*(1-O27)*O27*F27 -> 0.088764001
B28: 2 | C28: 4.5 | D28: 2.3 | E28: 1.3 | F28: 0.3 | G28: 0 | I28: =I27-K4*T27 -> 0.3635533 | J28: =J27-K4*U27 -> -0.42199986 | K28: =K27-K4*V27 -> -0.01266223 | L28: =L27-K4*W27 -> 0.79733688 | M28: =M27-K4*X27 -> 0.66082776 | N28: =I28+J28*C28+K28*D28+L28*E28+F28*M28 -> -0.32978293 | O28: =1/(1+EXP(-N28)) -> 0.41829344 | P28: =IF(O28>0.5,1,0) -> 0 | Q28: =O28-G28 -> 0.41829344 | R28: =Q28^2 -> 0.1749694 | T28: =2*(O28-G28)*(1-O28)*O28 -> 0.2035617 | U28: =2*(O28-G28)*(1-O28)*O28*C28 -> 0.91602764 | V28: =2*(O28-G28)*(1-O28)*O28*D28 -> 0.4681919 | W28: =2*(O28-G28)*(1-O28)*O28*E28 -> 0.26463021 | X28: =2*(O28-G28)*(1-O28)*O28*F28 -> 0.061068509
B29: 3 | C29: 4.4 | D29: 3.2 | E29: 1.3 | F29: 0.2 | G29: 0 | I29: =I28-K4*T28 -> 0.34319713 | J29: =J28-K4*U28 -> -0.51360263 | K29: =K28-K4*V28 -> -0.05948142 | L29: =L28-K4*W28 -> 0.77087386 | M29: =M28-K4*X28 -> 0.65472091 | N29: =I29+J29*C29+K29*D29+L29*E29+F29*M29 -> -0.97391477 | O29: =1/(1+EXP(-N29)) -> 0.27410089 | P29: =IF(O29>0.5,1,0) -> 0 | Q29: =O29-G29 -> 0.27410089 | R29: =Q29^2 -> 0.0751313 | T29: =2*(O29-G29)*(1-O29)*O29 -> 0.10907549 | U29: =2*(O29-G29)*(1-O29)*O29*C29 -> 0.47993214 | V29: =2*(O29-G29)*(1-O29)*O29*D29 -> 0.34904156 | W29: =2*(O29-G29)*(1-O29)*O29*E29 -> 0.14179813 | X29: =2*(O29-G29)*(1-O29)*O29*F29 -> 0.021815097
B30: 4 | C30: 5 | D30: 3.5 | E30: 1.6 | F30: 0.6 | G30: 0 | I30: =I29-K4*T29 -> 0.33228958 | J30: =J29-K4*U29 -> -0.56159584 | K30: =K29-K4*V29 -> -0.094385576 | L30: =L29-K4*W29 -> 0.75669405 | M30: =M29-K4*X29 -> 0.6525394 | N30: =I30+J30*C30+K30*D30+L30*E30+F30*M30 -> -1.203805 | O30: =1/(1+EXP(-N30)) -> 0.23079902 | P30: =IF(O30>0.5,1,0) -> 0 | Q30: =O30-G30 -> 0.23079902 | R30: =Q30^2 -> 0.053268186 | T30: =2*(O30-G30)*(1-O30)*O30 -> 0.081947882 | U30: =2*(O30-G30)*(1-O30)*O30*C30 -> 0.40973941 | V30: =2*(O30-G30)*(1-O30)*O30*D30 -> 0.28681759 | W30: =2*(O30-G30)*(1-O30)*O30*E30 -> 0.13111661 | X30: =2*(O30-G30)*(1-O30)*O30*F30 -> 0.049168729
B31: 5 | C31: 5.1 | D31: 3.8 | E31: 1.9 | F31: 0.4 | G31: 0 | I31: =I30-K4*T30 -> 0.32409479 | J31: =J30-K4*U30 -> -0.60256978 | K31: =K30-K4*V30 -> -0.12306733 | L31: =L30-K4*W30 -> 0.74358239 | M31: =M30-K4*X30 -> 0.64762253 | N31: =I31+J31*C31+K31*D31+L31*E31+F31*M31 -> -1.5448114 | O31: =1/(1+EXP(-N31)) -> 0.17583692 | P31: =IF(O31>0.5,1,0) -> 0 | Q31: =O31-G31 -> 0.17583692 | R31: =Q31^2 -> 0.030918624 | T31: =2*(O31-G31)*(1-O31)*O31 -> 0.050963977 | U31: =2*(O31-G31)*(1-O31)*O31*C31 -> 0.25991628 | V31: =2*(O31-G31)*(1-O31)*O31*D31 -> 0.19366311 | W31: =2*(O31-G31)*(1-O31)*O31*E31 -> 0.096831555 | X31: =2*(O31-G31)*(1-O31)*O31*F31 -> 0.020385591
B32: 6 | C32: 4.8 | D32: 3 | E32: 1.4 | F32: 0.3 | G32: 0 | I32: =I31-K4*T31 -> 0.31899839 | J32: =J31-K4*U31 -> -0.62856141 | K32: =K31-K4*V31 -> -0.14243365 | L32: =L31-K4*W31 -> 0.73389923 | M32: =M31-K4*X31 -> 0.64558397 | N32: =I32+J32*C32+K32*D32+L32*E32+F32*M32 -> -1.9042632 | O32: =1/(1+EXP(-N32)) -> 0.12962673 | P32: =IF(O32>0.5,1,0) -> 0 | Q32: =O32-G32 -> 0.12962673 | R32: =Q32^2 -> 0.016803088 | T32: =2*(O32-G32)*(1-O32)*O32 -> 0.029249917 | U32: =2*(O32-G32)*(1-O32)*O32*C32 -> 0.1403996 | V32: =2*(O32-G32)*(1-O32)*O32*D32 -> 0.087749752 | W32: =2*(O32-G32)*(1-O32)*O32*E32 -> 0.040949884 | X32: =2*(O32-G32)*(1-O32)*O32*F32 -> 0.0087749752
B33: 7 | C33: 5.1 | D33: 3.8 | E33: 1.6 | F33: 0.2 | G33: 0 | I33: =I32-K4*T32 -> 0.3160734 | J33: =J32-K4*U32 -> -0.64260137 | K33: =K32-K4*V32 -> -0.15120862 | L33: =L32-K4*W32 -> 0.72980425 | M33: =M32-K4*X32 -> 0.64470647 | N33: =I33+J33*C33+K33*D33+L33*E33+F33*M33 -> -2.2391583 | O33: =1/(1+EXP(-N33)) -> 0.096288763 | P33: =IF(O33>0.5,1,0) -> 0 | Q33: =O33-G33 -> 0.096288763 | R33: =Q33^2 -> 0.0092715258 | T33: =2*(O33-G33)*(1-O33)*O33 -> 0.016757564 | U33: =2*(O33-G33)*(1-O33)*O33*C33 -> 0.085463577 | V33: =2*(O33-G33)*(1-O33)*O33*D33 -> 0.063678744 | W33: =2*(O33-G33)*(1-O33)*O33*E33 -> 0.026812103 | X33: =2*(O33-G33)*(1-O33)*O33*F33 -> 0.0033515128
B34: 8 | C34: 4.6 | D34: 3.2 | E34: 1.4 | F34: 0.2 | G34: 0 | I34: =I33-K4*T33 -> 0.31439765 | J34: =J33-K4*U33 -> -0.65114773 | K34: =K33-K4*V33 -> -0.1575765 | L34: =L33-K4*W33 -> 0.72712304 | M34: =M33-K4*X33 -> 0.64437132 | N34: =I34+J34*C34+K34*D34+L34*E34+F34*M34 -> -2.0382802 | O34: =1/(1+EXP(-N34)) -> 0.11524197 | P34: =IF(O34>0.5,1,0) -> 0 | Q34: =O34-G34 -> 0.11524197 | R34: =Q34^2 -> 0.013280712 | T34: =2*(O34-G34)*(1-O34)*O34 -> 0.023500433 | U34: =2*(O34-G34)*(1-O34)*O34*C34 -> 0.10810199 | V34: =2*(O34-G34)*(1-O34)*O34*D34 -> 0.075201386 | W34: =2*(O34-G34)*(1-O34)*O34*E34 -> 0.032900606 | X34: =2*(O34-G34)*(1-O34)*O34*F34 -> 0.0047000866
B35: 9 | C35: 5.3 | D35: 3.7 | E35: 1.5 | F35: 0.2 | G35: 0 | I35: =I34-K4*T34 -> 0.3120476 | J35: =J34-K4*U34 -> -0.66195793 | K35: =K34-K4*V34 -> -0.16509663 | L35: =L34-K4*W34 -> 0.72383297 | M35: =M34-K4*X34 -> 0.64390131 | N35: =I35+J35*C35+K35*D35+L35*E35+F35*M35 -> -2.5926572 | O35: =1/(1+EXP(-N35)) -> 0.069612486 | P35: =IF(O35>0.5,1,0) -> 0 | Q35: =O35-G35 -> 0.069612486 | R35: =Q35^2 -> 0.0048458982 | T35: =2*(O35-G35)*(1-O35)*O35 -> 0.0090171264 | U35: =2*(O35-G35)*(1-O35)*O35*C35 -> 0.04779077 | V35: =2*(O35-G35)*(1-O35)*O35*D35 -> 0.033363368 | W35: =2*(O35-G35)*(1-O35)*O35*E35 -> 0.01352569 | X35: =2*(O35-G35)*(1-O35)*O35*F35 -> 0.0018034253
B36: 10 | C36: 5 | D36: 3.3 | E36: 1.4 | F36: 0.2 | G36: 0 | I36: =I35-K4*T35 -> 0.31114589 | J36: =J35-K4*U35 -> -0.666737 | K36: =K35-K4*V35 -> -0.16843297 | L36: =L35-K4*W35 -> 0.72248041 | M36: =M35-K4*X35 -> 0.64372097 | N36: =I36+J36*C36+K36*D36+L36*E36+F36*M36 -> -2.4381512 | O36: =1/(1+EXP(-N36)) -> 0.08030936 | P36: =IF(O36>0.5,1,0) -> 0 | Q36: =O36-G36 -> 0.08030936 | R36: =Q36^2 -> 0.0064495933 | T36: =2*(O36-G36)*(1-O36)*O36 -> 0.011863261 | U36: =2*(O36-G36)*(1-O36)*O36*C36 -> 0.059316306 | V36: =2*(O36-G36)*(1-O36)*O36*D36 -> 0.039148762 | W36: =2*(O36-G36)*(1-O36)*O36*E36 -> 0.016608566 | X36: =2*(O36-G36)*(1-O36)*O36*F36 -> 0.0023726522
B37: 11 | C37: 5.5 | D37: 2.6 | E37: 4.4 | F37: 1.2 | G37: 1 | I37: =I36-K4*T36 -> 0.30995956 | J37: =J36-K4*U36 -> -0.67266863 | K37: =K36-K4*V36 -> -0.17234785 | L37: =L36-K4*W36 -> 0.72081955 | M37: =M36-K4*X36 -> 0.6434837 | N37: =I37+J37*C37+K37*D37+L37*E37+F37*M37 -> 0.10596413 | O37: =1/(1+EXP(-N37)) -> 0.52646627 | P37: =IF(O37>0.5,1,0) -> 1 | Q37: =O37-G37 -> -0.47353373 | R37: =Q37^2 -> 0.22423419 | T37: =2*(O37-G37)*(1-O37)*O37 -> -0.23610348 | U37: =2*(O37-G37)*(1-O37)*O37*C37 -> -1.2985691 | V37: =2*(O37-G37)*(1-O37)*O37*D37 -> -0.61386904 | W37: =2*(O37-G37)*(1-O37)*O37*E37 -> -1.0388553 | X37: =2*(O37-G37)*(1-O37)*O37*F37 -> -0.28332417
B38: 12 | C38: 6.1 | D38: 3 | E38: 4.6 | F38: 1.4 | G38: 1 | I38: =I37-K4*T37 -> 0.33356991 | J38: =J37-K4*U37 -> -0.54281172 | K38: =K37-K4*V37 -> -0.11096094 | L38: =L37-K4*W37 -> 0.82470508 | M38: =M37-K4*X37 -> 0.67181612 | N38: =I38+J38*C38+K38*D38+L38*E38+F38*M38 -> 1.4237215 | O38: =1/(1+EXP(-N38)) -> 0.80592117 | P38: =IF(O38>0.5,1,0) -> 1 | Q38: =O38-G38 -> -0.19407883 | R38: =Q38^2 -> 0.037666593 | T38: =2*(O38-G38)*(1-O38)*O38 -> -0.060712609 | U38: =2*(O38-G38)*(1-O38)*O38*C38 -> -0.37034691 | V38: =2*(O38-G38)*(1-O38)*O38*D38 -> -0.18213783 | W38: =2*(O38-G38)*(1-O38)*O38*E38 -> -0.279278 | X38: =2*(O38-G38)*(1-O38)*O38*F38 -> -0.084997652
B39: 13 | C39: 5.8 | D39: 2.6 | E39: 4 | F39: 1.2 | G39: 1 | I39: =I38-K4*T38 -> 0.33964117 | J39: =J38-K4*U38 -> -0.50577703 | K39: =K38-K4*V38 -> -0.09274716 | L39: =L38-K4*W38 -> 0.85263288 | M39: =M38-K4*X38 -> 0.68031589 | N39: =I39+J39*C39+K39*D39+L39*E39+F39*M39 -> 1.3919024 | O39: =1/(1+EXP(-N39)) -> 0.80089577 | P39: =IF(O39>0.5,1,0) -> 1 | Q39: =O39-G39 -> -0.19910423 | R39: =Q39^2 -> 0.039642494 | T39: =2*(O39-G39)*(1-O39)*O39 -> -0.063499012 | U39: =2*(O39-G39)*(1-O39)*O39*C39 -> -0.36829427 | V39: =2*(O39-G39)*(1-O39)*O39*D39 -> -0.16509743 | W39: =2*(O39-G39)*(1-O39)*O39*E39 -> -0.25399605 | X39: =2*(O39-G39)*(1-O39)*O39*F39 -> -0.076198815
B40: 14 | C40: 5 | D40: 2.3 | E40: 3.3 | F40: 1 | G40: 1 | I40: =I39-K4*T39 -> 0.34599107 | J40: =J39-K4*U39 -> -0.4689476 | K40: =K39-K4*V39 -> -0.076237417 | L40: =L39-K4*W39 -> 0.87803248 | M40: =M39-K4*X39 -> 0.68793577 | N40: =I40+J40*C40+K40*D40+L40*E40+F40*M40 -> 1.41135 | O40: =1/(1+EXP(-N40)) -> 0.80397878 | P40: =IF(O40>0.5,1,0) -> 1 | Q40: =O40-G40 -> -0.19602122 | R40: =Q40^2 -> 0.038424318 | T40: =2*(O40-G40)*(1-O40)*O40 -> -0.061784673 | U40: =2*(O40-G40)*(1-O40)*O40*C40 -> -0.30892337 | V40: =2*(O40-G40)*(1-O40)*O40*D40 -> -0.14210475 | W40: =2*(O40-G40)*(1-O40)*O40*E40 -> -0.20388942 | X40: =2*(O40-G40)*(1-O40)*O40*F40 -> -0.061784673
B41: 15 | C41: 5.6 | D41: 2.7 | E41: 4.2 | F41: 1.3 | G41: 1 | I41: =I40-K4*T40 -> 0.35216954 | J41: =J40-K4*U40 -> -0.43805527 | K41: =K40-K4*V40 -> -0.062026942 | L41: =L40-K4*W40 -> 0.89842143 | M41: =M40-K4*X40 -> 0.69411423 | N41: =I41+J41*C41+K41*D41+L41*E41+F41*M41 -> 2.4073058 | O41: =1/(1+EXP(-N41)) -> 0.91738271 | P41: =IF(O41>0.5,1,0) -> 1 | Q41: =O41-G41 -> -0.082617287 | R41: =Q41^2 -> 0.0068256161 | T41: =2*(O41-G41)*(1-O41)*O41 -> -0.012523404 | U41: =2*(O41-G41)*(1-O41)*O41*C41 -> -0.070131065 | V41: =2*(O41-G41)*(1-O41)*O41*D41 -> -0.033813192 | W41: =2*(O41-G41)*(1-O41)*O41*E41 -> -0.052598298 | X41: =2*(O41-G41)*(1-O41)*O41*F41 -> -0.016280426
...
